{"active":1699724459691,"date":0,"event":"draft","input":" ","sender_id":"5c499089-21c4-49b2-9f56-0db0d58dd3f4"}
{"date":"2023-11-11T17:18:43.760Z","event":"chat","history":[{"author_id":"5c499089-21c4-49b2-9f56-0db0d58dd3f4","content":"<span class=\"user-mention\" account-id=openai-gpt-3.5-turbo >@GPT-3.5</span> Explain the following Python 3 (system-wide) code that is in a Jupyter notebook:\n\n<details>\n\n\n```python\ndataset=pd.DataFrame({\"walking_with_dogs\":[9,7,10,12],\"walking_without_dogs\":[4,5,3,6,51]})\n```\n\n\n</details>","date":"2023-11-11T17:18:43.760Z"}],"sender_id":"5c499089-21c4-49b2-9f56-0db0d58dd3f4"}
{"date":"2023-11-11T17:18:43.766Z","event":"chat","generating":false,"history":[{"author_id":"openai-gpt-3.5-turbo","content":" code creates a pandas DataFrame called \"dataset\". The dataset has columns: \"walking_with_dogs\" and \"walking_without_dogs\". The values in the \"walking_with_dogs\" column are 9, 7, 10, and 12. The values in the \"walking_without_dogs\" column are 4, 5, 3, 6, and 51.","date":"2023-11-11T17:18:43.766Z"}],"reply_to":"2023-11-11T17:18:43.760Z","sender_id":"openai-gpt-3.5-turbo"}
{"date":"2023-11-11T17:19:13.588Z","event":"chat","history":[{"author_id":"5c499089-21c4-49b2-9f56-0db0d58dd3f4","content":"<span class=\"user-mention\" account-id=openai-gpt-3.5-turbo >@GPT-3.5</span> help me fix my code.\n\n<details><summary>Context</summary>\n\n\nI ran a cell in a Jupyter notebook.\n\nI received the following error:\n\n```python\n---------------------------------------------------------------------------\nValueError                                Traceback (most recent call last)\nCell In[13], line 1\n----> 1 dataset=pd.DataFrame({\"walking_with_dogs\":[9,7,10,12],\n      2                      \"walking_without_dogs\":[4,5,3,6,51]})\n\nFile ~/.local/lib/python3.10/site-packages/pandas/core/frame.py:664, in DataFrame.__init__(self, data, index, columns, dtype, copy)\n    658     mgr = self._init_mgr(\n    659         data, axes={\"index\": index, \"columns\": columns}, dtype=dtype, copy=copy\n    660     )\n    662 elif isinstance(data, dict):\n    663     # GH#38939 de facto copy defaults to False only in non-dict cases\n--> 664     mgr = dict_to_mgr(data, index, columns, dtype=dtype, copy=copy, typ=manager)\n    665 elif isinstance(data, ma.MaskedArray):\n    666     import numpy.ma.mrecords as mrecords\n\nFile ~/.local/lib/python3.10/site-packages/pandas/core/internals/construction.py:493, in dict_to_mgr(data, index, columns, dtype, typ, copy)\n    489     else:\n    490         # dtype check to exclude e.g. range objects, scalars\n    491         arrays = [x.copy() if hasattr(x, \"dtype\") else x for x in arrays]\n--> 493 return arrays_to_mgr(arrays, columns, index, dtype=dtype, typ=typ, consolidate=copy)\n\nFile ~/.local/lib/python3.10/site-packages/pandas/core/internals/construction.py:118, in arrays_to_mgr(arrays, columns, index, dtype, verify_integrity, typ, consolidate)\n    115 if verify_integrity:\n    116     # figure out the index, if necessary\n    117     if index is None:\n--> 118         index = _extract_index(arrays)\n    119     else:\n    120         index = ensure_index(index)\n\nFile ~/.local/lib/python3.10/site-packages/pandas/core/internals/construction.py:666, in _extract_index(data)\n    664 lengths = list(set(raw_lengths))\n    665 if len(lengths) > 1:\n--> 666     raise ValueError(\"All arrays must be of the same length\")\n    668 if have_dicts:\n    669     raise ValueError(\n    670         \"Mixing dicts with non-Series may lead to ambiguous ordering.\"\n    671     )\n\nValueError: All arrays must be of the same length\n```\n\n\nMy Jupyter notebook using the Python 3 (system-wide) kernel contains:\n\n```python\ndataset=pd.DataFrame({\"walking_with_dogs\":[9,7,10,12],\"walking_without_dogs\":[4,5,3,6,51]})\n```\n\n\n\n</details>","date":"2023-11-11T17:19:13.588Z"}],"sender_id":"5c499089-21c4-49b2-9f56-0db0d58dd3f4"}
{"date":"2023-11-11T17:19:13.594Z","event":"chat","generating":false,"history":[{"author_id":"openai-gpt-3.5-turbo","content":" error message indicates that the arrays you are using to create the DataFrame have different lengths. In this case, the \"walking_with_dogs\" array has 4 elements, while the \"walking_without_dogs\" array has 5 elements.\n\nTo fix this issue, make sure that the arrays you use to create the DataFrame have the same length. You can either add a missing value (e.g., `None` or `np.nan`) to the shorter array or remove the extra element from the longer array.\n\nHere's an example of adding a missing value to the \"walking_with_dogs\" array:\n\n```python\ndataset = pd.DataFrame({\"walking_with_dogs\": [9, 7, 10, 12, None],\n                       \"walking_without_dogs\": [4, 5, 3, 6, 51]})\n```\n\nAlternatively, you can remove the extra element from the \"walking_without_dogs\" array:\n\n```python\ndataset = pd.DataFrame({\"walking_with_dogs\": [9, 7, 10, 12],\n                       \"walking_without_dogs\": [4, 5, 3, 6]})\n```\n\nChoose the approach that suits your data and requirements.","date":"2023-11-11T17:19:13.594Z"}],"reply_to":"2023-11-11T17:19:13.588Z","sender_id":"openai-gpt-3.5-turbo"}
{"date":"2023-11-11T17:35:39.615Z","event":"chat","history":[{"author_id":"5c499089-21c4-49b2-9f56-0db0d58dd3f4","content":"<span class=\"user-mention\" account-id=openai-gpt-3.5-turbo >@GPT-3.5</span> help me fix my code.\n\n<details><summary>Context</summary>\n\n\nI ran a cell in a Jupyter notebook.\n\nI received the following error:\n\n```python\n---------------------------------------------------------------------------\nValueError                                Traceback (most recent call last)\nCell In[21], line 23\n     20 kurtosis = dataset.apply(lambda x: scipy.stats.kurtosis(x))\n     22 # Combine the results into a new DataFrame\n---> 23 summary_statistics = pd.DataFrame({\n     24     'Confidence Interval': confidence_interval,\n     25     'Trimmed Mean (5%)': trimmed_mean_5percent,\n     26     'Median': median,\n     27     'Variance': variance,\n     28     'Range': data_range,\n     29     'Interquartile Range': iqr,\n     30     'Skewness': skewness,\n     31     'Kurtosis': kurtosis\n     32 })\n     34 print(summary_statistics)\n--> 664     mgr = dict_to_mgr(data, index, columns, dtype=dtype, copy=copy, typ=manager)\n--> 493 return arrays_to_mgr(arrays, columns, index, dtype=dtype, typ=typ, consolidate=copy)\n--> 123     arrays = _homogenize(arrays, index, dtype)\n--> 617     val = sanitize_array(\n    645             subarr = maybe_infer_to_datetimelike(subarr)\n--> 647 subarr = _sanitize_ndim(subarr, data, dtype, index, allow_2d=allow_2d)\n    649 if isinstance(subarr, np.ndarray):\n    650     # at this point we should have dtype be None or subarr.dtype == dtype\n    651     dtype = cast(np.dtype, dtype)\n\nFile ~/.local/lib/python3.10/site-packages/pandas/core/construction.py:698, in _sanitize_ndim(result, data, dtype, index, allow_2d)\n    696     if allow_2d:\n    697         return result\n--> 698     raise ValueError(\"Data must be 1-dimensional\")\n    699 if is_object_dtype(dtype) and isinstance(dtype, ExtensionDtype):\n    700     # i.e. PandasDtype(\"O\")\n    702     result = com.asarray_tuplesafe(data, dtype=np.dtype(\"object\"))\n\nValueError: Data must be 1-dimensional\n```\n\n\nMy Jupyter notebook using the Python 3 (system-wide) kernel contains:\n\n```python\nimport pandas as pd\nimport scipy.stats\n\n# Your dataset\ndataset = pd.DataFrame({\"walking_with_dogs\": [9, 7, 10, 12, 6, 8],\n                        \"walking_without_dogs\": [4, 5, 3, 6, 5, 1]})\n\n# Function to calculate 5% trimmed mean\ndef trimmed_mean(data, trim_percent):\n    return scipy.stats.trim_mean(data, trim_percent)\n\n# Additional statistics\nconfidence_interval = dataset.apply(lambda x: scipy.stats.t.interval(0.95, len(x)-1, loc=x.mean(), scale=scipy.stats.sem(x)))\ntrimmed_mean_5percent = dataset.apply(lambda x: trimmed_mean(x, 0.05))\nmedian = dataset.median()\nvariance = dataset.var()\ndata_range = dataset.apply(lambda x: x.max() - x.min())\niqr = dataset.apply(lambda x: scipy.stats.iqr(x))\nskewness = dataset.apply(lambda x: scipy.stats.skew(x))\nkurtosis = dataset.apply(lambda x: scipy.stats.kurtosis(x))\n\n# Combine the results into a new DataFrame\nsummary_statistics = pd.DataFrame({\n    'Confidence Interval': confidence_interval,\n    'Trimmed Mean (5%)': trimmed_mean_5percent,\n    'Median': median,\n    'Variance': variance,\n    'Range': data_range,\n    'Interquartile Range': iqr,\n    'Skewness': skewness,\n    'Kurtosis': kurtosis\n})\n\nprint(summary_statistics)\n```\n\n\n\n</details>","date":"2023-11-11T17:35:39.615Z"}],"sender_id":"5c499089-21c4-49b2-9f56-0db0d58dd3f4"}
{"date":"2023-11-11T17:35:39.621Z","event":"chat","generating":false,"history":[{"author_id":"openai-gpt-3.5-turbo","content":" seems that you have a ValueError: Data must be 1-dimensional when trying to create the summary_statistics DataFrame. This error occurs because you are applying lambda functions to calculate summary statistics on the entire dataset, which results in applying these calculations to each column separately. As a result, the final DataFrame has multiple columns instead of one.\n\nTo fix this, you can modify your code to calculate summary statistics on each column individually and then combine the results into a new DataFrame. Here's the modified code:\n\n```python\nimport pandas as pd\nimport scipy.stats\n\n# Your dataset\ndataset = pd.DataFrame({\"walking_with_dogs\": [9, 7, 10, 12, 6, 8],\n                        \"walking_without_dogs\": [4, 5, 3, 6, 5, 1]})\n\n# Function to calculate 5% trimmed mean\ndef trimmed_mean(data, trim_percent):\n    return scipy.stats.trim_mean(data, trim_percent)\n\n# Additional statistics\nsummary = {}\nfor column in dataset.columns:\n    confidence_interval = scipy.stats.t.interval(0.95, len(dataset[column])-1, loc=dataset[column].mean(), scale=scipy.stats.sem(dataset[column]))\n    trimmed_mean_5percent = trimmed_mean(dataset[column], 0.05)\n    median = dataset[column].median()\n    variance = dataset[column].var()\n    data_range = dataset[column].max() - dataset[column].min()\n    iqr = scipy.stats.iqr(dataset[column])\n    skewness = scipy.stats.skew(dataset[column])\n    kurtosis = scipy.stats.kurtosis(dataset[column])\n\n    stats = {\n        'Confidence Interval': confidence_interval,\n        'Trimmed Mean (5%)': trimmed_mean_5percent,\n        'Median': median,\n        'Variance': variance,\n        'Range': data_range,\n        'Interquartile Range': iqr,\n        'Skewness': skewness,\n        'Kurtosis': kurtosis\n    }\n\n    summary[column] = stats\n\nsummary_statistics = pd.DataFrame(summary)\n\nprint(summary_statistics)\n```\n\nIn this modified code, we iterate over each column in the dataset and calculate the summary statistics for each column individually. We then store the results in the `summary` dictionary using the column names as keys. Finally, we create the `summary_statistics` DataFrame from the `summary` dictionary.\n\nThis should fix the error and give you the desired output for your summary statistics. Let me know if you have any more questions.","date":"2023-11-11T17:35:39.621Z"}],"reply_to":"2023-11-11T17:35:39.615Z","sender_id":"openai-gpt-3.5-turbo"}
{"date":"2023-11-11T17:40:59.733Z","event":"chat","history":[{"author_id":"5c499089-21c4-49b2-9f56-0db0d58dd3f4","content":"<span class=\"user-mention\" account-id=openai-gpt-3.5-turbo >@GPT-3.5</span> help me fix my code.\n\n<details><summary>Context</summary>\n\n\nI ran a cell in a Jupyter notebook.\n\nI received the following error:\n\n```python\n---------------------------------------------------------------------------\nAttributeError                            Traceback (most recent call last)\nCell In[24], line 12\n      9     return x.quantile(0.05), x.quantile(0.95)\n     11 # Calculate summary statistics\n---> 12 summary_statistics = dataset.agg(['mean', 'std', 'min', '25%', '50%', '75%', 'max', trimmed_mean_5percent, 'var', 'ptp', 'quantile', 'skew', 'kurt'])\n     14 # Transpose for better readability\n     15 summary_statistics = summary_statistics.T.rename(columns={'50%': 'Median', 'trimmed_mean_5percent': 'Trimmed Mean (5%)'})\n\nFile ~/.local/lib/python3.10/site-packages/pandas/core/frame.py:9342, in DataFrame.aggregate(self, func, axis, *args, **kwargs)\n   9339 relabeling, func, columns, order = reconstruct_func(func, **kwargs)\n   9341 op = frame_apply(self, func=func, axis=axis, args=args, kwargs=kwargs)\n-> 9342 result = op.agg()\n   9344 if relabeling:\n   9345     # This is to keep the order to columns occurrence unchanged, and also\n   9346     # keep the order of new columns occurrence unchanged\n--> 776     result = super().agg()\n--> 175     return self.agg_list_like()\n--> 401         new_res = colg.aggregate(arg)\n-> 4605 result = op.agg()\n-> 1126     result = super().agg()\n--> 175     return self.agg_list_like()\n--> 378     new_res = colg.aggregate(a)\n-> 4605 result = op.agg()\n-> 1126     result = super().agg()\n--> 169     return self.apply_str()\n\nFile ~/.local/lib/python3.10/site-packages/pandas/core/apply.py:580, in Apply.apply_str(self)\n    578     elif self.axis != 0:\n    579         raise ValueError(f\"Operation {f} does not support axis=1\")\n--> 580 return self._try_aggregate_string_function(obj, f, *self.args, **self.kwargs)\n\nFile ~/.local/lib/python3.10/site-packages/pandas/core/apply.py:662, in Apply._try_aggregate_string_function(self, obj, arg, *args, **kwargs)\n    658 if f is not None and hasattr(obj, \"__array__\"):\n    659     # in particular exclude Window\n    660     return f(obj, *args, **kwargs)\n--> 662 raise AttributeError(\n    663     f\"'{arg}' is not a valid function for '{type(obj).__name__}' object\"\n    664 )\n\nAttributeError: '25%' is not a valid function for 'Series' object\n```\n\n\nMy Jupyter notebook using the Python 3 (system-wide) kernel contains:\n\n```python\nimport pandas as pd\n\n# Your dataset\ndataset = pd.DataFrame({\"walking_with_dogs\": [9, 7, 10, 12, 6, 8],\n                        \"walking_without_dogs\": [4, 5, 3, 6, 5, 1]})\n\n# Define a function for 5% trimmed mean\ndef trimmed_mean_5percent(x):\n    return x.quantile(0.05), x.quantile(0.95)\n\n# Calculate summary statistics\nsummary_statistics = dataset.agg(['mean', 'std', 'min', '25%', '50%', '75%', 'max', trimmed_mean_5percent, 'var', 'ptp', 'quantile', 'skew', 'kurt'])\n\n# Transpose for better readability\nsummary_statistics = summary_statistics.T.rename(columns={'50%': 'Median', 'trimmed_mean_5percent': 'Trimmed Mean (5%)'})\n\nprint(summary_statistics)\n```\n\n\n\n</details>","date":"2023-11-11T17:40:59.733Z"}],"sender_id":"5c499089-21c4-49b2-9f56-0db0d58dd3f4"}
{"date":"2023-11-11T17:40:59.739Z","event":"chat","generating":false,"history":[{"author_id":"openai-gpt-3.5-turbo","content":" error message indicates that the function `trimmed_mean_5percent` is not compatible with the `agg` method used on a `Series` object. To fix the code, you can modify the `trimmed_mean_5percent` function to work with a `Series` object by using the `apply` method.\n\nReplace the line:\n```python\nreturn x.quantile(0.05), x.quantile(0.95)\n```\n\nwith:\n```python\nreturn pd.Series([x.quantile(0.05), x.quantile(0.95)], index=['5%', '95%'])\n```\n\nThis change will return a `Series` object with two elements, labeled as '5%' and '95%', instead of a tuple.\n\nThe updated code should look like this:\n\n```python\nimport pandas as pd\n\n# Your dataset\ndataset = pd.DataFrame({\"walking_with_dogs\": [9, 7, 10, 12, 6, 8],\n                        \"walking_without_dogs\": [4, 5, 3, 6, 5, 1]})\n\n# Define a function for 5% trimmed mean\ndef trimmed_mean_5percent(x):\n    return pd.Series([x.quantile(0.05), x.quantile(0.95)], index=['5%', '95%'])\n\n# Calculate summary statistics\nsummary_statistics = dataset.agg(['mean', 'std', 'min', '25%', '50%', '75%', 'max', trimmed_mean_5percent, 'var', 'ptp', 'quantile', 'skew', 'kurt'])\n\n# Transpose for better readability\nsummary_statistics = summary_statistics.T.rename(columns={'50%': 'Median', 'trimmed_mean_5percent': 'Trimmed Mean (5%)'})\n\nprint(summary_statistics)\n```\n\nThis should fix the error and give you the desired summary statistics.","date":"2023-11-11T17:40:59.739Z"}],"reply_to":"2023-11-11T17:40:59.733Z","sender_id":"openai-gpt-3.5-turbo"}